Workbook

Sheet 25. BANCO DE DADOS
A1: Empresa | B1: Mês | C1: Valor | D1: % Mensal | F1: Resumo de Resultados Líquido sem OL
A2: EMS MARCAS | B2: Janeiro | C2: 238283.02 | D2: 0.148072
A3: TEUTO | B3: Janeiro | C3: 228386.47 | D3: 0.141922 | F3: Mês | G3: 25. Resultado | H3: 24. Resultado | I3: ↑↓% | J3: MaM | L3: Quadrimestre | M3: 25. Resultado | N3: 24. Resultado | O3: ↑↓%
A4: GEOLAB | B4: Janeiro | C4: 194132.43 | D4: 0.120637 | F4: Janeiro | G4: =SUMIF(Tabela1[Mês],Tabela2[[#This Row],[Mês]],Tabela1[Valor]) -> 1609233.9 | H4: =SUMIF(Tabela18[Mês],Tabela2[[#This Row],[Mês]],Tabela18[Valor]) -> 968723.97 | I4: =IFERROR((Tabela2[[#This Row],[25. Resultado]]/Tabela2[[#This Row],[24. Resultado]]),"") -> 1.6611893 | J4: 0 | L4: Q1 | M4: =SUM(G4:G7) -> 6254294.9 | N4: =Tabela9[[#This Row],[24. Resultado]] -> 4043041.9 | O4: =IFERROR(Tabela3[[#This Row],[25. Resultado]]/Tabela3[[#This Row],[24. Resultado]],"") -> 1.5469281
A5: FORTLIFE | B5: Janeiro | C5: 117865.18 | D5: 0.073243 | F5: Fevereiro | G5: =SUMIF(Tabela1[Mês],Tabela2[[#This Row],[Mês]],Tabela1[Valor]) -> 1384804.6 | H5: =SUMIF(Tabela18[Mês],Tabela2[[#This Row],[Mês]],Tabela18[Valor]) -> 939367.07 | I5: =IFERROR((Tabela2[[#This Row],[25. Resultado]]/Tabela2[[#This Row],[24. Resultado]]),"") -> 1.474189 | J5: =IFERROR((Tabela2[[#This Row],[25. Resultado]]/G4)-1,"") -> -0.13946347 | L5: Q2 | M5: =SUM(G8:G11) -> 4550959.2 | N5: =Tabela9[[#This Row],[24. Resultado]] -> 4777240 | O5: =IFERROR(Tabela3[[#This Row],[25. Resultado]]/Tabela3[[#This Row],[24. Resultado]],"") -> 0.95263357
A6: BIOSINTETICA (ACHE) | B6: Janeiro | C6: 83508.83 | D6: 0.051894 | F6: Março | G6: =SUMIF(Tabela1[Mês],Tabela2[[#This Row],[Mês]],Tabela1[Valor]) -> 1665670.2 | H6: =SUMIF(Tabela18[Mês],Tabela2[[#This Row],[Mês]],Tabela18[Valor]) -> 1172270.8 | I6: =IFERROR((Tabela2[[#This Row],[25. Resultado]]/Tabela2[[#This Row],[24. Resultado]]),"") -> 1.4208921 | J6: =IFERROR((Tabela2[[#This Row],[25. Resultado]]/G5)-1,"") -> 0.2028197 | L6: Q3 | M6: =SUM(G12:G15) -> 5226795.3 | N6: =Tabela9[[#This Row],[24. Resultado]] -> 5767396.9 | O6: =IFERROR(Tabela3[[#This Row],[25. Resultado]]/Tabela3[[#This Row],[24. Resultado]],"") -> 0.90626594
A7: NUTRIEX INDUSTRIA DE COSMETICOS | B7: Janeiro | C7: 78899.45 | D7: 0.049029 | F7: Abril | G7: =SUMIF(Tabela1[Mês],Tabela2[[#This Row],[Mês]],Tabela1[Valor]) -> 1594586.2 | H7: =SUMIF(Tabela18[Mês],Tabela2[[#This Row],[Mês]],Tabela18[Valor]) -> 962680.09 | I7: =IFERROR((Tabela2[[#This Row],[25. Resultado]]/Tabela2[[#This Row],[24. Resultado]]),"") -> 1.656403 | J7: =IFERROR((Tabela2[[#This Row],[25. Resultado]]/G6)-1,"") -> -0.042675956
A8: PRUDENCE | B8: Janeiro | C8: 68680.41 | D8: 0.042679 | F8: Maio | G8: =SUMIF(Tabela1[Mês],Tabela2[[#This Row],[Mês]],Tabela1[Valor]) -> 1929362.9 | H8: =SUMIF(Tabela18[Mês],Tabela2[[#This Row],[Mês]],Tabela18[Valor]) -> 1209465.3 | I8: =IFERROR((Tabela2[[#This Row],[25. Resultado]]/Tabela2[[#This Row],[24. Resultado]]),"") -> 1.5952198 | J8: =IFERROR((Tabela2[[#This Row],[25. Resultado]]/G7)-1,"") -> 0.20994586
A9: PRINCIPIA | B9: Janeiro | C9: 51024.92 | D9: 0.031708 | F9: Junho | G9: 270899.38 | H9: =SUMIF(Tabela18[Mês],Tabela2[[#This Row],[Mês]],Tabela18[Valor]) -> 1212174.2 | I9: =IFERROR((Tabela2[[#This Row],[25. Resultado]]/Tabela2[[#This Row],[24. Resultado]]),"") -> 0.22348222 | J9: =IFERROR((Tabela2[[#This Row],[25. Resultado]]/G8)-1,"") -> -0.85959128
A10: HIDROLIGHT | B10: Janeiro | C10: 49910.54 | D10: 0.031015 | F10: Julho | G10: =SUMIF(Tabela1[Mês],Tabela2[[#This Row],[Mês]],Tabela1[Valor]) -> 852090.49 | H10: =SUMIF(Tabela18[Mês],Tabela2[[#This Row],[Mês]],Tabela18[Valor]) -> 1244445 | I10: =IFERROR((Tabela2[[#This Row],[25. Resultado]]/Tabela2[[#This Row],[24. Resultado]]),"") -> 0.68471526 | J10: =IFERROR((Tabela2[[#This Row],[25. Resultado]]/G9)-1,"") -> 2.1454132
A11: NUK | B11: Janeiro | C11: 45398 | D11: 0.028211 | F11: Agosto | G11: =SUMIF(Tabela1[Mês],Tabela2[[#This Row],[Mês]],Tabela1[Valor]) -> 1498606.4 | H11: =SUMIF(Tabela18[Mês],Tabela2[[#This Row],[Mês]],Tabela18[Valor]) -> 1111155.5 | I11: =IFERROR((Tabela2[[#This Row],[25. Resultado]]/Tabela2[[#This Row],[24. Resultado]]),"") -> 1.3486919 | J11: =IFERROR((Tabela2[[#This Row],[25. Resultado]]/G10)-1,"") -> 0.75874086 | L11: Trimestre | M11: 25. Resultado | N11: 24. Resultado | O11: ↑↓%
A12: MAXINUTRI | B12: Janeiro | C12: 38192.04 | D12: 0.023733 | F12: Setembro | G12: =SUMIF(Tabela1[Mês],Tabela2[[#This Row],[Mês]],Tabela1[Valor]) -> 1377471.1 | H12: =SUMIF(Tabela18[Mês],Tabela2[[#This Row],[Mês]],Tabela18[Valor]) -> 1167981.4 | I12: =IFERROR((Tabela2[[#This Row],[25. Resultado]]/Tabela2[[#This Row],[24. Resultado]]),"") -> 1.1793605 | J12: =IFERROR((Tabela2[[#This Row],[25. Resultado]]/G11)-1,"") -> -0.080831907 | L12: T1 | M12: =SUM(G4:G6) -> 4659708.8 | N12: =Tabela10[[#This Row],[24. Resultado]] -> 3080361.8 | O12: =IFERROR(Tabela4[[#This Row],[25. Resultado]]/Tabela4[[#This Row],[24. Resultado]],"") -> 1.5127148
A13: AIRELA | B13: Janeiro | C13: 30632.61 | D13: 0.019036 | F13: Outubro | G13: =SUMIF(Tabela1[Mês],Tabela2[[#This Row],[Mês]],Tabela1[Valor]) -> 1396971.1 | H13: =SUMIF(Tabela18[Mês],Tabela2[[#This Row],[Mês]],Tabela18[Valor]) -> 1388037.8 | I13: =IFERROR((Tabela2[[#This Row],[25. Resultado]]/Tabela2[[#This Row],[24. Resultado]]),"") -> 1.0064359 | J13: =IFERROR((Tabela2[[#This Row],[25. Resultado]]/G12)-1,"") -> 0.014156326 | L13: T2 | M13: =SUM(G7:G9) -> 3794848.5 | N13: =Tabela10[[#This Row],[24. Resultado]] -> 3384319.6 | O13: =IFERROR(Tabela4[[#This Row],[25. Resultado]]/Tabela4[[#This Row],[24. Resultado]],"") -> 1.1213032
A14: NATULAB | B14: Janeiro | C14: 30578.75 | D14: 0.019002 | F14: Novembro | G14: =SUMIF(Tabela1[Mês],Tabela2[[#This Row],[Mês]],Tabela1[Valor]) -> 1165277 | H14: =SUMIF(Tabela18[Mês],Tabela2[[#This Row],[Mês]],Tabela18[Valor]) -> 1723812.8 | I14: =IFERROR((Tabela2[[#This Row],[25. Resultado]]/Tabela2[[#This Row],[24. Resultado]]),"") -> 0.67598814 | J14: =IFERROR((Tabela2[[#This Row],[25. Resultado]]/G13)-1,"") -> -0.16585461 | L14: T3 | M14: =SUM(G10:G12) -> 3728168 | N14: =Tabela10[[#This Row],[24. Resultado]] -> 3523581.9 | O14: =IFERROR(Tabela4[[#This Row],[25. Resultado]]/Tabela4[[#This Row],[24. Resultado]],"") -> 1.058062
A15: BELLIZ | B15: Janeiro | C15: 28432.79 | D15: 0.017669 | F15: Dezembro | G15: 1287076.1 | H15: =SUMIF(Tabela18[Mês],Tabela2[[#This Row],[Mês]],Tabela18[Valor]) -> 1487564.9 | I15: =IFERROR((Tabela2[[#This Row],[25. Resultado]]/Tabela2[[#This Row],[24. Resultado]]),"") -> 0.86522352 | J15: =IFERROR((Tabela2[[#This Row],[25. Resultado]]/G14)-1,"") -> 0.10452375 | L15: T4 | M15: =SUM(G13:G15) -> 3849324.2 | N15: =Tabela10[[#This Row],[24. Resultado]] -> 4599415.4 | O15: =IFERROR(Tabela4[[#This Row],[25. Resultado]]/Tabela4[[#This Row],[24. Resultado]],"") -> 0.83691596
A16: BRASTERAPICA | B16: Janeiro | C16: 26767.14 | D16: 0.016633 | M16: =SUM(M12:M15) -> 16032049 | N16: 14587679 | O16: =M16/N16 -> 1.0990131
A17: NEO QUIMICA | B17: Janeiro | C17: 26524.6 | D17: 0.016483
A18: GLOBO | B18: Janeiro | C18: 26378.97 | D18: 0.016392 | F18: Ranking Anual | L18: Ranking Mensal
A19: ELOFAR | B19: Janeiro | C19: 25824.04 | D19: 0.016047
A20: LEGRAND | B20: Janeiro | C20: 25359.28 | D20: 0.015759 | L20: Pesquisa Mês: | M20: Janeiro
A21: COPAPHARMA | B21: Janeiro | C21: 18016.88 | D21: 0.011196 | F21: Laboratório | G21: 25. Fat. | H21: 24. Fat | I21: ↑↓% | L21: Empresa | M21: 25. Fat. | N21: 24. Fat | O21: ↑↓%
A22: BLAU | B22: Janeiro | C22: 17160.86 | D22: 0.010664 | F22: TEUTO | G22: 2207826.4 | H22: 2242986.3 | I22: =IFERROR(Tabela5[[#This Row],[25. Fat.]]/Tabela5[[#This Row],[24. Fat]],"") -> 0.98432448 | L22: EMS MARCAS | M22: =SUMIFS(Tabela1[Valor],Tabela1[Empresa],Tabela6[[#This Row],[Empresa]],Tabela1[Mês],$M$20) -> 238283.02 | N22: =SUMIFS(Tabela18[Valor],Tabela18[Empresa],Tabela6[[#This Row],[Empresa]],Tabela18[Mês],'25. BANCO DE DADOS'!$M$20) -> 264992.46 | O22: =IFERROR(Tabela6[[#This Row],[25. Fat.]]/Tabela6[[#This Row],[24. Fat]],"") -> 0.89920679
A23: NOVAQUIMICA | B23: Janeiro | C23: 12955.07 | D23: 0.00805 | F23: BIOSINTETICA | G23: 1610592.6 | H23: 1890453.6 | I23: =IFERROR(Tabela5[[#This Row],[25. Fat.]]/Tabela5[[#This Row],[24. Fat]],"") -> 0.85196092 | L23: TEUTO | M23: =SUMIFS(Tabela1[Valor],Tabela1[Empresa],Tabela6[[#This Row],[Empresa]],Tabela1[Mês],$M$20) -> 228386.47 | N23: =SUMIFS(Tabela18[Valor],Tabela18[Empresa],Tabela6[[#This Row],[Empresa]],Tabela18[Mês],'25. BANCO DE DADOS'!$M$20) -> 178015.29 | O23: =IFERROR(Tabela6[[#This Row],[25. Fat.]]/Tabela6[[#This Row],[24. Fat]],"") -> 1.2829599
A24: MEDQUIMICA | B24: Janeiro | C24: 10457.98 | D24: 0.006499 | F24: GEOLAB | G24: 1482113.7 | H24: 1569490.1 | I24: =IFERROR(Tabela5[[#This Row],[25. Fat.]]/Tabela5[[#This Row],[24. Fat]],"") -> 0.94432818 | L24: GEOLAB | M24: =SUMIFS(Tabela1[Valor],Tabela1[Empresa],Tabela6[[#This Row],[Empresa]],Tabela1[Mês],$M$20) -> 194132.43 | N24: =SUMIFS(Tabela18[Valor],Tabela18[Empresa],Tabela6[[#This Row],[Empresa]],Tabela18[Mês],'25. BANCO DE DADOS'!$M$20) -> 62739.65 | O24: =IFERROR(Tabela6[[#This Row],[25. Fat.]]/Tabela6[[#This Row],[24. Fat]],"") -> 3.0942543
A25: ABL | B25: Janeiro | C25: 10448.66 | D25: 0.006493 | F25: EMS MARCAS | G25: 1359487.1 | H25: 994873.55 | I25: =IFERROR(Tabela5[[#This Row],[25. Fat.]]/Tabela5[[#This Row],[24. Fat]],"") -> 1.3664923 | L25: FORTLIFE | M25: =SUMIFS(Tabela1[Valor],Tabela1[Empresa],Tabela6[[#This Row],[Empresa]],Tabela1[Mês],$M$20) -> 117865.18 | N25: =SUMIFS(Tabela18[Valor],Tabela18[Empresa],Tabela6[[#This Row],[Empresa]],Tabela18[Mês],'25. BANCO DE DADOS'!$M$20) -> 0 | O25: =IFERROR(Tabela6[[#This Row],[25. Fat.]]/Tabela6[[#This Row],[24. Fat]],"")
A26: MANTECORP FARMASA | B26: Janeiro | C26: 10427.27 | D26: 0.00648 | F26: FORTLIFE | G26: 966514.31 | H26: 961945.43 | I26: =IFERROR(Tabela5[[#This Row],[25. Fat.]]/Tabela5[[#This Row],[24. Fat]],"") -> 1.0047496 | L26: BIOSINTETICA (ACHE) | M26: =SUMIFS(Tabela1[Valor],Tabela1[Empresa],Tabela6[[#This Row],[Empresa]],Tabela1[Mês],$M$20) -> 83508.83 | N26: =SUMIFS(Tabela18[Valor],Tabela18[Empresa],Tabela6[[#This Row],[Empresa]],Tabela18[Mês],'25. BANCO DE DADOS'!$M$20) -> 33300.42 | O26: =IFERROR(Tabela6[[#This Row],[25. Fat.]]/Tabela6[[#This Row],[24. Fat]],"") -> 2.507741
A27: ZYDUS NIKKHO | B27: Janeiro | C27: 10180.22 | D27: 0.006326 | F27: PRUDENCE | G27: 945728.26 | H27: 661745.48 | I27: =IFERROR(Tabela5[[#This Row],[25. Fat.]]/Tabela5[[#This Row],[24. Fat]],"") -> 1.429142 | L27: NUTRIEX INDUSTRIA DE COSMETICOS | M27: =SUMIFS(Tabela1[Valor],Tabela1[Empresa],Tabela6[[#This Row],[Empresa]],Tabela1[Mês],$M$20) -> 78899.45 | N27: =SUMIFS(Tabela18[Valor],Tabela18[Empresa],Tabela6[[#This Row],[Empresa]],Tabela18[Mês],'25. BANCO DE DADOS'!$M$20) -> 15386.97 | O27: =IFERROR(Tabela6[[#This Row],[25. Fat.]]/Tabela6[[#This Row],[24. Fat]],"") -> 5.1276795
A28: EMS GENERICO | B28: Janeiro | C28: 8661.07 | D28: 0.005382 | F28: HIDROLIGHT | G28: 927288.18 | H28: 542161.1 | I28: =IFERROR(Tabela5[[#This Row],[25. Fat.]]/Tabela5[[#This Row],[24. Fat]],"") -> 1.7103554 | L28: PRUDENCE | M28: =SUMIFS(Tabela1[Valor],Tabela1[Empresa],Tabela6[[#This Row],[Empresa]],Tabela1[Mês],$M$20) -> 68680.41 | N28: =SUMIFS(Tabela18[Valor],Tabela18[Empresa],Tabela6[[#This Row],[Empresa]],Tabela18[Mês],'25. BANCO DE DADOS'!$M$20) -> 0 | O28: =IFERROR(Tabela6[[#This Row],[25. Fat.]]/Tabela6[[#This Row],[24. Fat]],"")
A29: POLIBRINQ | B29: Janeiro | C29: 7848.39 | D29: 0.004877 | F29: PRINCIPIA | G29: 433688.25 | H29: 513811.94 | I29: =IFERROR(Tabela5[[#This Row],[25. Fat.]]/Tabela5[[#This Row],[24. Fat]],"") -> 0.84406028 | L29: PRINCIPIA | M29: =SUMIFS(Tabela1[Valor],Tabela1[Empresa],Tabela6[[#This Row],[Empresa]],Tabela1[Mês],$M$20) -> 51024.92 | N29: 90850.6 | O29: =IFERROR(Tabela6[[#This Row],[25. Fat.]]/Tabela6[[#This Row],[24. Fat]],"") -> 0.56163548
A30: MEDLEVENSOHN | B30: Janeiro | C30: 7165.02 | D30: 0.004452 | F30: NATULAB | G30: 394497.77 | H30: 490458.54 | I30: =IFERROR(Tabela5[[#This Row],[25. Fat.]]/Tabela5[[#This Row],[24. Fat]],"") -> 0.80434479 | L30: HIDROLIGHT | M30: =SUMIFS(Tabela1[Valor],Tabela1[Empresa],Tabela6[[#This Row],[Empresa]],Tabela1[Mês],$M$20) -> 49910.54 | N30: =SUMIFS(Tabela18[Valor],Tabela18[Empresa],Tabela6[[#This Row],[Empresa]],Tabela18[Mês],'25. BANCO DE DADOS'!$M$20) -> 105525.19 | O30: =IFERROR(Tabela6[[#This Row],[25. Fat.]]/Tabela6[[#This Row],[24. Fat]],"") -> 0.47297276
A31: DOVALLE | B31: Janeiro | C31: 7008.02 | D31: 0.004355 | F31: MAXINUTRI | G31: 387173.28 | H31: 409504.38 | I31: =IFERROR(Tabela5[[#This Row],[25. Fat.]]/Tabela5[[#This Row],[24. Fat]],"") -> 0.94546798 | L31: NUK | M31: =SUMIFS(Tabela1[Valor],Tabela1[Empresa],Tabela6[[#This Row],[Empresa]],Tabela1[Mês],$M$20) -> 45398 | N31: =SUMIFS(Tabela18[Valor],Tabela18[Empresa],Tabela6[[#This Row],[Empresa]],Tabela18[Mês],'25. BANCO DE DADOS'!$M$20) -> 78203.14 | O31: =IFERROR(Tabela6[[#This Row],[25. Fat.]]/Tabela6[[#This Row],[24. Fat]],"") -> 0.58051377
A32: EUROFARMA | B32: Janeiro | C32: 5117.73 | D32: 0.00318 | F32: NUK | G32: 367568.47 | H32: 402078.19 | I32: =IFERROR(Tabela5[[#This Row],[25. Fat.]]/Tabela5[[#This Row],[24. Fat]],"") -> 0.91417162 | L32: MAXINUTRI | M32: =SUMIFS(Tabela1[Valor],Tabela1[Empresa],Tabela6[[#This Row],[Empresa]],Tabela1[Mês],$M$20) -> 38192.04 | N32: =SUMIFS(Tabela18[Valor],Tabela18[Empresa],Tabela6[[#This Row],[Empresa]],Tabela18[Mês],'25. BANCO DE DADOS'!$M$20) -> 11472.63 | O32: =IFERROR(Tabela6[[#This Row],[25. Fat.]]/Tabela6[[#This Row],[24. Fat]],"") -> 3.3289699
A33: AS ERVAS CURAM | B33: Janeiro | C33: 4852.97 | D33: 0.003016 | F33: NEO QUIMICA | G33: 345664.83 | H33: 362256.1 | I33: =IFERROR(Tabela5[[#This Row],[25. Fat.]]/Tabela5[[#This Row],[24. Fat]],"") -> 0.95420016 | L33: AIRELA | M33: =SUMIFS(Tabela1[Valor],Tabela1[Empresa],Tabela6[[#This Row],[Empresa]],Tabela1[Mês],$M$20) -> 30632.61 | N33: =SUMIFS(Tabela18[Valor],Tabela18[Empresa],Tabela6[[#This Row],[Empresa]],Tabela18[Mês],'25. BANCO DE DADOS'!$M$20) -> 13120.38 | O33: =IFERROR(Tabela6[[#This Row],[25. Fat.]]/Tabela6[[#This Row],[24. Fat]],"") -> 2.334735
A34: MEDLEY | B34: Janeiro | C34: 4750.75 | D34: 0.002952 | F34: BLAU | G34: 333908.6 | H34: 355143.66 | I34: =IFERROR(Tabela5[[#This Row],[25. Fat.]]/Tabela5[[#This Row],[24. Fat]],"") -> 0.94020713 | L34: NATULAB | M34: =SUMIFS(Tabela1[Valor],Tabela1[Empresa],Tabela6[[#This Row],[Empresa]],Tabela1[Mês],$M$20) -> 30578.75 | N34: =SUMIFS(Tabela18[Valor],Tabela18[Empresa],Tabela6[[#This Row],[Empresa]],Tabela18[Mês],'25. BANCO DE DADOS'!$M$20) -> 37124.16 | O34: =IFERROR(Tabela6[[#This Row],[25. Fat.]]/Tabela6[[#This Row],[24. Fat]],"") -> 0.82368867
A35: BELFAR | B35: Janeiro | C35: 4481.38 | D35: 0.002785 | F35: GLOBO | G35: 320079.12 | H35: 343913.59 | I35: =IFERROR(Tabela5[[#This Row],[25. Fat.]]/Tabela5[[#This Row],[24. Fat]],"") -> 0.93069634 | L35: BELLIZ | M35: =SUMIFS(Tabela1[Valor],Tabela1[Empresa],Tabela6[[#This Row],[Empresa]],Tabela1[Mês],$M$20) -> 28432.79 | N35: =SUMIFS(Tabela18[Valor],Tabela18[Empresa],Tabela6[[#This Row],[Empresa]],Tabela18[Mês],'25. BANCO DE DADOS'!$M$20) -> 0 | O35: =IFERROR(Tabela6[[#This Row],[25. Fat.]]/Tabela6[[#This Row],[24. Fat]],"")
A36: IRIDIUM LABS | B36: Janeiro | C36: 4352.61 | D36: 0.002705 | F36: NUTRIEX INDUSTRIA DE COSMETICOS | G36: 318617.12 | H36: 227756.18 | I36: =IFERROR(Tabela5[[#This Row],[25. Fat.]]/Tabela5[[#This Row],[24. Fat]],"") -> 1.3989395 | L36: BRASTERAPICA | M36: =SUMIFS(Tabela1[Valor],Tabela1[Empresa],Tabela6[[#This Row],[Empresa]],Tabela1[Mês],$M$20) -> 26767.14 | N36: =SUMIFS(Tabela18[Valor],Tabela18[Empresa],Tabela6[[#This Row],[Empresa]],Tabela18[Mês],'25. BANCO DE DADOS'!$M$20) -> 5546.26 | O36: =IFERROR(Tabela6[[#This Row],[25. Fat.]]/Tabela6[[#This Row],[24. Fat]],"") -> 4.8261603
A37: FQM | B37: Janeiro | C37: 4215.44 | D37: 0.00262 | F37: AIRELA | G37: 305166.81 | H37: 190948.18 | I37: =IFERROR(Tabela5[[#This Row],[25. Fat.]]/Tabela5[[#This Row],[24. Fat]],"") -> 1.5981656 | L37: NEO QUIMICA | M37: =SUMIFS(Tabela1[Valor],Tabela1[Empresa],Tabela6[[#This Row],[Empresa]],Tabela1[Mês],$M$20) -> 26524.6 | N37: =SUMIFS(Tabela18[Valor],Tabela18[Empresa],Tabela6[[#This Row],[Empresa]],Tabela18[Mês],'25. BANCO DE DADOS'!$M$20) -> 13213.33 | O37: =IFERROR(Tabela6[[#This Row],[25. Fat.]]/Tabela6[[#This Row],[24. Fat]],"") -> 2.0074122
A38: ROSA SELVAGEM | B38: Janeiro | C38: 3845.04 | D38: 0.002389 | F38: BELLIZ | G38: 304795.14 | H38: 163739.17 | I38: =IFERROR(Tabela5[[#This Row],[25. Fat.]]/Tabela5[[#This Row],[24. Fat]],"") -> 1.8614675 | L38: GLOBO | M38: =SUMIFS(Tabela1[Valor],Tabela1[Empresa],Tabela6[[#This Row],[Empresa]],Tabela1[Mês],$M$20) -> 26378.97 | N38: =SUMIFS(Tabela18[Valor],Tabela18[Empresa],Tabela6[[#This Row],[Empresa]],Tabela18[Mês],'25. BANCO DE DADOS'!$M$20) -> 8099 | O38: =IFERROR(Tabela6[[#This Row],[25. Fat.]]/Tabela6[[#This Row],[24. Fat]],"") -> 3.2570651
A39: NATIVITA | B39: Janeiro | C39: 3232.97 | D39: 0.002009 | F39: BRASTERAPICA | G39: 295326.36 | H39: 97668.37 | I39: =IFERROR(Tabela5[[#This Row],[25. Fat.]]/Tabela5[[#This Row],[24. Fat]],"") -> 3.0237667 | L39: ELOFAR | M39: =SUMIFS(Tabela1[Valor],Tabela1[Empresa],Tabela6[[#This Row],[Empresa]],Tabela1[Mês],$M$20) -> 25824.04 | N39: =SUMIFS(Tabela18[Valor],Tabela18[Empresa],Tabela6[[#This Row],[Empresa]],Tabela18[Mês],'25. BANCO DE DADOS'!$M$20) -> 44556.61 | O39: =IFERROR(Tabela6[[#This Row],[25. Fat.]]/Tabela6[[#This Row],[24. Fat]],"") -> 0.5795782
A40: UNIPHAR | B40: Janeiro | C40: 2993.08 | D40: 0.00186 | F40: ELOFAR | G40: 213676.22 | H40: 92178.42 | I40: =IFERROR(Tabela5[[#This Row],[25. Fat.]]/Tabela5[[#This Row],[24. Fat]],"") -> 2.3180721 | L40: LEGRAND | M40: =SUMIFS(Tabela1[Valor],Tabela1[Empresa],Tabela6[[#This Row],[Empresa]],Tabela1[Mês],$M$20) -> 25359.28 | N40: =SUMIFS(Tabela18[Valor],Tabela18[Empresa],Tabela6[[#This Row],[Empresa]],Tabela18[Mês],'25. BANCO DE DADOS'!$M$20) -> 5949.22 | O40: =IFERROR(Tabela6[[#This Row],[25. Fat.]]/Tabela6[[#This Row],[24. Fat]],"") -> 4.2626227
...

Sheet 24. BANCO DE DADOS
A1: Empresa | B1: Mês | C1: Valor | D1: % Mensal | F1: Resumo de Resultados
A2: EMS MARCAS | B2: Janeiro | C2: 264992.46 | D2: 0.273548
A3: TEUTO | B3: Janeiro | C3: 178015.29 | D3: 0.183763 | F3: Mês | G3: 24. Resultado | I3: Quadrimestre | J3: 24. Resultado
A4: HIDROLIGHT | B4: Janeiro | C4: 105525.19 | D4: 0.108932 | F4: Janeiro | G4: =SUMIF(Tabela18[Mês],Tabela8[[#This Row],[Mês]],Tabela18[Valor]) -> 968723.97 | I4: Q1 | J4: =SUM(G4:G7) -> 4043041.9
A5: NUK | B5: Janeiro | C5: 78203.14 | D5: 0.080728 | F5: Fevereiro | G5: =SUMIF(Tabela18[Mês],Tabela8[[#This Row],[Mês]],Tabela18[Valor]) -> 939367.07 | I5: Q2 | J5: =SUM(G8:G11) -> 4777240
A6: GEOLAB | B6: Janeiro | C6: 62739.65 | D6: 0.064765 | F6: Março | G6: =SUMIF(Tabela18[Mês],Tabela8[[#This Row],[Mês]],Tabela18[Valor]) -> 1172270.8 | I6: Q3 | J6: =SUM(G12:G15) -> 5767396.9
A7: ELOFAR | B7: Janeiro | C7: 44556.61 | D7: 0.045995 | F7: Abril | G7: =SUMIF(Tabela18[Mês],Tabela8[[#This Row],[Mês]],Tabela18[Valor]) -> 962680.09
A8: NATULAB | B8: Janeiro | C8: 37124.16 | D8: 0.038323 | F8: Maio | G8: =SUMIF(Tabela18[Mês],Tabela8[[#This Row],[Mês]],Tabela18[Valor]) -> 1209465.3
A9: BIOSINTETICA (ACHE) | B9: Janeiro | C9: 33300.42 | D9: 0.034376 | F9: Junho | G9: =SUMIF(Tabela18[Mês],Tabela8[[#This Row],[Mês]],Tabela18[Valor]) -> 1212174.2
A10: NUTRIEX INDUSTRIA DE COSMETICOS | B10: Janeiro | C10: 15386.97 | D10: 0.015884 | F10: Julho | G10: =SUMIF(Tabela18[Mês],Tabela8[[#This Row],[Mês]],Tabela18[Valor]) -> 1244445
A11: NEO QUIMICA | B11: Janeiro | C11: 13213.33 | D11: 0.01364 | F11: Agosto | G11: =SUMIF(Tabela18[Mês],Tabela8[[#This Row],[Mês]],Tabela18[Valor]) -> 1111155.5 | I11: Trimestre | J11: 24. Resultado
A12: AIRELA | B12: Janeiro | C12: 13120.38 | D12: 0.013544 | F12: Setembro | G12: =SUMIF(Tabela18[Mês],Tabela8[[#This Row],[Mês]],Tabela18[Valor]) -> 1167981.4 | I12: T1 | J12: =SUM(G4:G6) -> 3080361.8
A13: MAXINUTRI | B13: Janeiro | C13: 11472.63 | D13: 0.011843 | F13: Outubro | G13: =SUMIF(Tabela18[Mês],Tabela8[[#This Row],[Mês]],Tabela18[Valor]) -> 1388037.8 | I13: T2 | J13: =SUM(G7:G9) -> 3384319.6
A14: VITAMEDIC | B14: Janeiro | C14: 10558.21 | D14: 0.010899 | F14: Novembro | G14: =SUMIF(Tabela18[Mês],Tabela8[[#This Row],[Mês]],Tabela18[Valor]) -> 1723812.8 | I14: T3 | J14: =SUM(G10:G12) -> 3523581.9
A15: IRIDIUM LABS | B15: Janeiro | C15: 9664.02 | D15: 0.009976 | F15: Dezembro | G15: =SUMIF(Tabela18[Mês],Tabela8[[#This Row],[Mês]],Tabela18[Valor]) -> 1487564.9 | I15: T4 | J15: =SUM(G13:G15) -> 4599415.4
A16: MANTECORP FARMASA | B16: Janeiro | C16: 8781.89 | D16: 0.009065 | I16: Total 2024 | J16: =SUM(J12:J15) -> 14587679
A17: BIOLAND | B17: Janeiro | C17: 8305.63 | D17: 0.008574
A18: GLOBO | B18: Janeiro | C18: 8099 | D18: 0.00836
A19: EMS GENERICO | B19: Janeiro | C19: 6748.76 | D19: 0.006967
A20: DOVALLE | B20: Janeiro | C20: 6476.54 | D20: 0.006686
A21: LEGRAND | B21: Janeiro | C21: 5949.22 | D21: 0.006141
A22: BRASTERAPICA | B22: Janeiro | C22: 5546.26 | D22: 0.005725
A23: CAZI | B23: Janeiro | C23: 5522.2 | D23: 0.0057
A24: EUROFARMA | B24: Janeiro | C24: 4202.31 | D24: 0.004338
A25: CREMER | B25: Janeiro | C25: 3403.51 | D25: 0.003513
A26: NOVAQUIMICA | B26: Janeiro | C26: 3350 | D26: 0.003458
A27: ABL | B27: Janeiro | C27: 2161.75 | D27: 0.002232
A28: UNIAO QUIMICA | B28: Janeiro | C28: 2107.62 | D28: 0.002176
... A260: GREEN | B260: Abril | C260: 60.56 | D260: 6.3e-05
B261: Abril | C261: 37.75 | D261: 3.9e-05
A262: CATARINENSE PHARMA | B262: Abril | C262: 37.32 | D262: 3.9e-05
A263: SR SALDANHA RODRIGUES | B263: Abril | C263: 34 | D263: 3.5e-05
A264: DRICA | B264: Abril | C264: 27 | D264: 2.8e-05
A265: SUPER SHAVE | B265: Abril | C265: 25.2 | D265: 2.6e-05
A266: HYPERMARCAS BOZZANO | B266: Abril | C266: 23.82 | D266: 2.5e-05
A267: RILEX | B267: Abril | C267: 22.14 | D267: 2.3e-05
A268: OTC - BIOWORLD | B268: Abril | C268: 8.99 | D268: 9e-06
A269: EMS MARCAS | B269: Maio | C269: 294125.17 | D269: 0.243186
A270: TEUTO | B270: Maio | C270: 165883.84 | D270: 0.137155
A271: GEOLAB | B271: Maio | C271: 140762.16 | D271: 0.116384
...

Sheet 26. BANCO DE DADOS
A1: Empresa | B1: Mês | C1: Valor | D1: % Mensal | F1: Resumo de Resultados Líquido sem OL
A2: EMS MARCAS | B2: Janeiro | C2: 238283.02 | D2: 0.148072
A3: TEUTO | B3: Janeiro | C3: 228386.47 | D3: 0.141922 | F3: Mês | G3: 26. Resultado 2 | H3: 25. Resultado 2 | I3: ↑↓% | J3: MaM | L3: Quadrimestre | M3: 26. Resultado 2 | N3: 25. Resultado 2 | O3: ↑↓%
A4: GEOLAB | B4: Janeiro | C4: 194132.43 | D4: 0.120637 | F4: Janeiro | G4: 1786638.6 | H4: 2197654.6 | I4: =IFERROR((Tabela214[[#This Row],[26. Resultado 2 ]]/Tabela214[[#This Row],[25. Resultado 2]]),"") -> 0.81297516 | J4: 0 | L4: Q1 | M4: =SUM(G4:G7) -> 5653656.3 | N4: 9859323.1 | O4: =IFERROR(Tabela315[[#This Row],[26. Resultado 2 ]]/Tabela315[[#This Row],[25. Resultado 2]],"") -> 0.5734325
A5: FORTLIFE | B5: Janeiro | C5: 117865.18 | D5: 0.073243 | F5: Fevereiro | G5: 1496232.1 | H5: 2414367.9 | I5: =IFERROR((Tabela214[[#This Row],[26. Resultado 2 ]]/Tabela214[[#This Row],[25. Resultado 2]]),"") -> 0.61972 | J5: =IFERROR((Tabela214[[#This Row],[26. Resultado 2 ]]/G4)-1,"") -> -0.16254353 | L5: Q2 | M5: =SUM(G8:G11) -> 0 | N5: 6181973.1 | O5: =IFERROR(Tabela315[[#This Row],[26. Resultado 2 ]]/Tabela315[[#This Row],[25. Resultado 2]],"") -> 0
A6: BIOSINTETICA (ACHE) | B6: Janeiro | C6: 83508.83 | D6: 0.051894 | F6: Março | G6: 2370785.6 | H6: 2863654.9 | I6: =IFERROR((Tabela214[[#This Row],[26. Resultado 2 ]]/Tabela214[[#This Row],[25. Resultado 2]]),"") -> 0.82788803 | J6: =IFERROR((Tabela214[[#This Row],[26. Resultado 2 ]]/G5)-1,"") -> 0.58450395 | L6: Q3 | M6: =SUM(G12:G15) -> 0 | N6: 7860525.6 | O6: =IFERROR(Tabela315[[#This Row],[26. Resultado 2 ]]/Tabela315[[#This Row],[25. Resultado 2]],"") -> 0
A7: NUTRIEX INDUSTRIA DE COSMETICOS | B7: Janeiro | C7: 78899.45 | D7: 0.049029 | F7: Abril | H7: 2383645.7 | I7: =IFERROR((Tabela214[[#This Row],[26. Resultado 2 ]]/Tabela214[[#This Row],[25. Resultado 2]]),"") -> 0 | J7: =IFERROR((Tabela214[[#This Row],[26. Resultado 2 ]]/G6)-1,"") -> -1 | M7: =SUM(M4:M6) -> 5653656.3 | N7: =SUM(N4:N6) -> 23901822
A8: PRUDENCE | B8: Janeiro | C8: 68680.41 | D8: 0.042679 | F8: Maio | H8: 2599591.5 | I8: =IFERROR((Tabela214[[#This Row],[26. Resultado 2 ]]/Tabela214[[#This Row],[25. Resultado 2]]),"") -> 0 | J8: =IFERROR((Tabela214[[#This Row],[26. Resultado 2 ]]/G7)-1,"")
A9: PRINCIPIA | B9: Janeiro | C9: 51024.92 | D9: 0.031708 | F9: Junho | H9: 353128.7 | I9: =IFERROR((Tabela214[[#This Row],[26. Resultado 2 ]]/Tabela214[[#This Row],[25. Resultado 2]]),"") -> 0 | J9: =IFERROR((Tabela214[[#This Row],[26. Resultado 2 ]]/G8)-1,"")
A10: HIDROLIGHT | B10: Janeiro | C10: 49910.54 | D10: 0.031015 | F10: Julho | H10: 1268984.1 | I10: =IFERROR((Tabela214[[#This Row],[26. Resultado 2 ]]/Tabela214[[#This Row],[25. Resultado 2]]),"") -> 0 | J10: =IFERROR((Tabela214[[#This Row],[26. Resultado 2 ]]/G9)-1,"")
A11: NUK | B11: Janeiro | C11: 45398 | D11: 0.028211 | F11: Agosto | H11: 1960268.8 | I11: =IFERROR((Tabela214[[#This Row],[26. Resultado 2 ]]/Tabela214[[#This Row],[25. Resultado 2]]),"") -> 0 | J11: =IFERROR((Tabela214[[#This Row],[26. Resultado 2 ]]/G10)-1,"") | L11: Trimestre | M11: 26. Resultado 2 | N11: 25. Resultado 2 | O11: ↑↓%
A12: MAXINUTRI | B12: Janeiro | C12: 38192.04 | D12: 0.023733 | F12: Setembro | H12: 1769818.4 | I12: =IFERROR((Tabela214[[#This Row],[26. Resultado 2 ]]/Tabela214[[#This Row],[25. Resultado 2]]),"") -> 0 | J12: =IFERROR((Tabela214[[#This Row],[26. Resultado 2 ]]/G11)-1,"") | L12: T1 | M12: =SUM(G4:G6) -> 5653656.3 | N12: 7475677.4 | O12: =IFERROR(Tabela416[[#This Row],[26. Resultado 2 ]]/Tabela416[[#This Row],[25. Resultado 2]],"") -> 0.75627345
A13: AIRELA | B13: Janeiro | C13: 30632.61 | D13: 0.019036 | F13: Outubro | H13: 2279625.6 | I13: =IFERROR((Tabela214[[#This Row],[26. Resultado 2 ]]/Tabela214[[#This Row],[25. Resultado 2]]),"") -> 0 | J13: =IFERROR((Tabela214[[#This Row],[26. Resultado 2 ]]/G12)-1,"") | L13: T2 | M13: =SUM(G7:G9) -> 0 | N13: 5336365.9 | O13: =IFERROR(Tabela416[[#This Row],[26. Resultado 2 ]]/Tabela416[[#This Row],[25. Resultado 2]],"") -> 0
A14: NATULAB | B14: Janeiro | C14: 30578.75 | D14: 0.019002 | F14: Novembro | H14: 1789056.9 | I14: =IFERROR((Tabela214[[#This Row],[26. Resultado 2 ]]/Tabela214[[#This Row],[25. Resultado 2]]),"") -> 0 | J14: =IFERROR((Tabela214[[#This Row],[26. Resultado 2 ]]/G13)-1,"") | L14: T3 | M14: =SUM(G10:G12) -> 0 | N14: 4999071.3 | O14: =IFERROR(Tabela416[[#This Row],[26. Resultado 2 ]]/Tabela416[[#This Row],[25. Resultado 2]],"") -> 0
A15: BELLIZ | B15: Janeiro | C15: 28432.79 | D15: 0.017669 | F15: Dezembro | H15: 2022024.7 | I15: =IFERROR((Tabela214[[#This Row],[26. Resultado 2 ]]/Tabela214[[#This Row],[25. Resultado 2]]),"") -> 0 | J15: =IFERROR((Tabela214[[#This Row],[26. Resultado 2 ]]/G14)-1,"") | L15: T4 | M15: =SUM(G13:G15) -> 0 | N15: 6090707.2 | O15: =IFERROR(Tabela416[[#This Row],[26. Resultado 2 ]]/Tabela416[[#This Row],[25. Resultado 2]],"") -> 0
A16: BRASTERAPICA | B16: Janeiro | C16: 26767.14 | D16: 0.016633 | M16: =SUM(M12:M15) -> 5653656.3 | N16: =SUM(N12:N15) -> 23901822 | O16: =M16/N16 -> 0.23653663
A17: NEO QUIMICA | B17: Janeiro | C17: 26524.6 | D17: 0.016483
A18: GLOBO | B18: Janeiro | C18: 26378.97 | D18: 0.016392 | F18: Ranking Anual | L18: Ranking Mensal
A19: ELOFAR | B19: Janeiro | C19: 25824.04 | D19: 0.016047
A20: LEGRAND | B20: Janeiro | C20: 25359.28 | D20: 0.015759 | L20: Pesquisa Mês: | M20: Janeiro
A21: COPAPHARMA | B21: Janeiro | C21: 18016.88 | D21: 0.011196 | F21: Laboratório | G21: 25. Fat. | H21: 24. Fat | I21: ↑↓% | L21: Empresa | M21: 25. Fat. | N21: 24. Fat | O21: ↑↓%
A22: BLAU | B22: Janeiro | C22: 17160.86 | D22: 0.010664 | F22: TEUTO | G22: 2207826.4 | H22: 2242986.3 | I22: =IFERROR(Tabela517[[#This Row],[25. Fat.]]/Tabela517[[#This Row],[24. Fat]],"") -> 0.98432448 | L22: EMS MARCAS | M22: =SUMIFS(Tabela113[Valor],Tabela113[Empresa],Tabela618[[#This Row],[Empresa]],Tabela113[Mês],$M$20) -> 238283.02 | N22: =SUMIFS(Tabela18[Valor],Tabela18[Empresa],Tabela618[[#This Row],[Empresa]],Tabela18[Mês],'25. BANCO DE DADOS'!$M$20) -> 264992.46 | O22: =IFERROR(Tabela618[[#This Row],[25. Fat.]]/Tabela618[[#This Row],[24. Fat]],"") -> 0.89920679
A23: NOVAQUIMICA | B23: Janeiro | C23: 12955.07 | D23: 0.00805 | F23: BIOSINTETICA | G23: 1610592.6 | H23: 1890453.6 | I23: =IFERROR(Tabela517[[#This Row],[25. Fat.]]/Tabela517[[#This Row],[24. Fat]],"") -> 0.85196092 | L23: TEUTO | M23: =SUMIFS(Tabela113[Valor],Tabela113[Empresa],Tabela618[[#This Row],[Empresa]],Tabela113[Mês],$M$20) -> 228386.47 | N23: =SUMIFS(Tabela18[Valor],Tabela18[Empresa],Tabela618[[#This Row],[Empresa]],Tabela18[Mês],'25. BANCO DE DADOS'!$M$20) -> 178015.29 | O23: =IFERROR(Tabela618[[#This Row],[25. Fat.]]/Tabela618[[#This Row],[24. Fat]],"") -> 1.2829599
A24: MEDQUIMICA | B24: Janeiro | C24: 10457.98 | D24: 0.006499 | F24: GEOLAB | G24: 1482113.7 | H24: 1569490.1 | I24: =IFERROR(Tabela517[[#This Row],[25. Fat.]]/Tabela517[[#This Row],[24. Fat]],"") -> 0.94432818 | L24: GEOLAB | M24: =SUMIFS(Tabela113[Valor],Tabela113[Empresa],Tabela618[[#This Row],[Empresa]],Tabela113[Mês],$M$20) -> 194132.43 | N24: =SUMIFS(Tabela18[Valor],Tabela18[Empresa],Tabela618[[#This Row],[Empresa]],Tabela18[Mês],'25. BANCO DE DADOS'!$M$20) -> 62739.65 | O24: =IFERROR(Tabela618[[#This Row],[25. Fat.]]/Tabela618[[#This Row],[24. Fat]],"") -> 3.0942543
A25: ABL | B25: Janeiro | C25: 10448.66 | D25: 0.006493 | F25: EMS MARCAS | G25: 1359487.1 | H25: 994873.55 | I25: =IFERROR(Tabela517[[#This Row],[25. Fat.]]/Tabela517[[#This Row],[24. Fat]],"") -> 1.3664923 | L25: FORTLIFE | M25: =SUMIFS(Tabela113[Valor],Tabela113[Empresa],Tabela618[[#This Row],[Empresa]],Tabela113[Mês],$M$20) -> 117865.18 | N25: =SUMIFS(Tabela18[Valor],Tabela18[Empresa],Tabela618[[#This Row],[Empresa]],Tabela18[Mês],'25. BANCO DE DADOS'!$M$20) -> 0 | O25: =IFERROR(Tabela618[[#This Row],[25. Fat.]]/Tabela618[[#This Row],[24. Fat]],"")
A26: MANTECORP FARMASA | B26: Janeiro | C26: 10427.27 | D26: 0.00648 | F26: FORTLIFE | G26: 966514.31 | H26: 961945.43 | I26: =IFERROR(Tabela517[[#This Row],[25. Fat.]]/Tabela517[[#This Row],[24. Fat]],"") -> 1.0047496 | L26: BIOSINTETICA (ACHE) | M26: =SUMIFS(Tabela113[Valor],Tabela113[Empresa],Tabela618[[#This Row],[Empresa]],Tabela113[Mês],$M$20) -> 83508.83 | N26: =SUMIFS(Tabela18[Valor],Tabela18[Empresa],Tabela618[[#This Row],[Empresa]],Tabela18[Mês],'25. BANCO DE DADOS'!$M$20) -> 33300.42 | O26: =IFERROR(Tabela618[[#This Row],[25. Fat.]]/Tabela618[[#This Row],[24. Fat]],"") -> 2.507741
A27: ZYDUS NIKKHO | B27: Janeiro | C27: 10180.22 | D27: 0.006326 | F27: PRUDENCE | G27: 945728.26 | H27: 661745.48 | I27: =IFERROR(Tabela517[[#This Row],[25. Fat.]]/Tabela517[[#This Row],[24. Fat]],"") -> 1.429142 | L27: NUTRIEX INDUSTRIA DE COSMETICOS | M27: =SUMIFS(Tabela113[Valor],Tabela113[Empresa],Tabela618[[#This Row],[Empresa]],Tabela113[Mês],$M$20) -> 78899.45 | N27: =SUMIFS(Tabela18[Valor],Tabela18[Empresa],Tabela618[[#This Row],[Empresa]],Tabela18[Mês],'25. BANCO DE DADOS'!$M$20) -> 15386.97 | O27: =IFERROR(Tabela618[[#This Row],[25. Fat.]]/Tabela618[[#This Row],[24. Fat]],"") -> 5.1276795
A28: EMS GENERICO | B28: Janeiro | C28: 8661.07 | D28: 0.005382 | F28: HIDROLIGHT | G28: 927288.18 | H28: 542161.1 | I28: =IFERROR(Tabela517[[#This Row],[25. Fat.]]/Tabela517[[#This Row],[24. Fat]],"") -> 1.7103554 | L28: PRUDENCE | M28: =SUMIFS(Tabela113[Valor],Tabela113[Empresa],Tabela618[[#This Row],[Empresa]],Tabela113[Mês],$M$20) -> 68680.41 | N28: =SUMIFS(Tabela18[Valor],Tabela18[Empresa],Tabela618[[#This Row],[Empresa]],Tabela18[Mês],'25. BANCO DE DADOS'!$M$20) -> 0 | O28: =IFERROR(Tabela618[[#This Row],[25. Fat.]]/Tabela618[[#This Row],[24. Fat]],"")
A29: POLIBRINQ | B29: Janeiro | C29: 7848.39 | D29: 0.004877 | F29: PRINCIPIA | G29: 433688.25 | H29: 513811.94 | I29: =IFERROR(Tabela517[[#This Row],[25. Fat.]]/Tabela517[[#This Row],[24. Fat]],"") -> 0.84406028 | L29: PRINCIPIA | M29: =SUMIFS(Tabela113[Valor],Tabela113[Empresa],Tabela618[[#This Row],[Empresa]],Tabela113[Mês],$M$20) -> 51024.92 | N29: 90850.6 | O29: =IFERROR(Tabela618[[#This Row],[25. Fat.]]/Tabela618[[#This Row],[24. Fat]],"") -> 0.56163548
A30: MEDLEVENSOHN | B30: Janeiro | C30: 7165.02 | D30: 0.004452 | F30: NATULAB | G30: 394497.77 | H30: 490458.54 | I30: =IFERROR(Tabela517[[#This Row],[25. Fat.]]/Tabela517[[#This Row],[24. Fat]],"") -> 0.80434479 | L30: HIDROLIGHT | M30: =SUMIFS(Tabela113[Valor],Tabela113[Empresa],Tabela618[[#This Row],[Empresa]],Tabela113[Mês],$M$20) -> 49910.54 | N30: =SUMIFS(Tabela18[Valor],Tabela18[Empresa],Tabela618[[#This Row],[Empresa]],Tabela18[Mês],'25. BANCO DE DADOS'!$M$20) -> 105525.19 | O30: =IFERROR(Tabela618[[#This Row],[25. Fat.]]/Tabela618[[#This Row],[24. Fat]],"") -> 0.47297276
A31: DOVALLE | B31: Janeiro | C31: 7008.02 | D31: 0.004355 | F31: MAXINUTRI | G31: 387173.28 | H31: 409504.38 | I31: =IFERROR(Tabela517[[#This Row],[25. Fat.]]/Tabela517[[#This Row],[24. Fat]],"") -> 0.94546798 | L31: NUK | M31: =SUMIFS(Tabela113[Valor],Tabela113[Empresa],Tabela618[[#This Row],[Empresa]],Tabela113[Mês],$M$20) -> 45398 | N31: =SUMIFS(Tabela18[Valor],Tabela18[Empresa],Tabela618[[#This Row],[Empresa]],Tabela18[Mês],'25. BANCO DE DADOS'!$M$20) -> 78203.14 | O31: =IFERROR(Tabela618[[#This Row],[25. Fat.]]/Tabela618[[#This Row],[24. Fat]],"") -> 0.58051377
A32: EUROFARMA | B32: Janeiro | C32: 5117.73 | D32: 0.00318 | F32: NUK | G32: 367568.47 | H32: 402078.19 | I32: =IFERROR(Tabela517[[#This Row],[25. Fat.]]/Tabela517[[#This Row],[24. Fat]],"") -> 0.91417162 | L32: MAXINUTRI | M32: =SUMIFS(Tabela113[Valor],Tabela113[Empresa],Tabela618[[#This Row],[Empresa]],Tabela113[Mês],$M$20) -> 38192.04 | N32: =SUMIFS(Tabela18[Valor],Tabela18[Empresa],Tabela618[[#This Row],[Empresa]],Tabela18[Mês],'25. BANCO DE DADOS'!$M$20) -> 11472.63 | O32: =IFERROR(Tabela618[[#This Row],[25. Fat.]]/Tabela618[[#This Row],[24. Fat]],"") -> 3.3289699
A33: AS ERVAS CURAM | B33: Janeiro | C33: 4852.97 | D33: 0.003016 | F33: NEO QUIMICA | G33: 345664.83 | H33: 362256.1 | I33: =IFERROR(Tabela517[[#This Row],[25. Fat.]]/Tabela517[[#This Row],[24. Fat]],"") -> 0.95420016 | L33: AIRELA | M33: =SUMIFS(Tabela113[Valor],Tabela113[Empresa],Tabela618[[#This Row],[Empresa]],Tabela113[Mês],$M$20) -> 30632.61 | N33: =SUMIFS(Tabela18[Valor],Tabela18[Empresa],Tabela618[[#This Row],[Empresa]],Tabela18[Mês],'25. BANCO DE DADOS'!$M$20) -> 13120.38 | O33: =IFERROR(Tabela618[[#This Row],[25. Fat.]]/Tabela618[[#This Row],[24. Fat]],"") -> 2.334735
A34: MEDLEY | B34: Janeiro | C34: 4750.75 | D34: 0.002952 | F34: BLAU | G34: 333908.6 | H34: 355143.66 | I34: =IFERROR(Tabela517[[#This Row],[25. Fat.]]/Tabela517[[#This Row],[24. Fat]],"") -> 0.94020713 | L34: NATULAB | M34: =SUMIFS(Tabela113[Valor],Tabela113[Empresa],Tabela618[[#This Row],[Empresa]],Tabela113[Mês],$M$20) -> 30578.75 | N34: =SUMIFS(Tabela18[Valor],Tabela18[Empresa],Tabela618[[#This Row],[Empresa]],Tabela18[Mês],'25. BANCO DE DADOS'!$M$20) -> 37124.16 | O34: =IFERROR(Tabela618[[#This Row],[25. Fat.]]/Tabela618[[#This Row],[24. Fat]],"") -> 0.82368867
A35: BELFAR | B35: Janeiro | C35: 4481.38 | D35: 0.002785 | F35: GLOBO | G35: 320079.12 | H35: 343913.59 | I35: =IFERROR(Tabela517[[#This Row],[25. Fat.]]/Tabela517[[#This Row],[24. Fat]],"") -> 0.93069634 | L35: BELLIZ | M35: =SUMIFS(Tabela113[Valor],Tabela113[Empresa],Tabela618[[#This Row],[Empresa]],Tabela113[Mês],$M$20) -> 28432.79 | N35: =SUMIFS(Tabela18[Valor],Tabela18[Empresa],Tabela618[[#This Row],[Empresa]],Tabela18[Mês],'25. BANCO DE DADOS'!$M$20) -> 0 | O35: =IFERROR(Tabela618[[#This Row],[25. Fat.]]/Tabela618[[#This Row],[24. Fat]],"")
A36: IRIDIUM LABS | B36: Janeiro | C36: 4352.61 | D36: 0.002705 | F36: NUTRIEX INDUSTRIA DE COSMETICOS | G36: 318617.12 | H36: 227756.18 | I36: =IFERROR(Tabela517[[#This Row],[25. Fat.]]/Tabela517[[#This Row],[24. Fat]],"") -> 1.3989395 | L36: BRASTERAPICA | M36: =SUMIFS(Tabela113[Valor],Tabela113[Empresa],Tabela618[[#This Row],[Empresa]],Tabela113[Mês],$M$20) -> 26767.14 | N36: =SUMIFS(Tabela18[Valor],Tabela18[Empresa],Tabela618[[#This Row],[Empresa]],Tabela18[Mês],'25. BANCO DE DADOS'!$M$20) -> 5546.26 | O36: =IFERROR(Tabela618[[#This Row],[25. Fat.]]/Tabela618[[#This Row],[24. Fat]],"") -> 4.8261603
A37: FQM | B37: Janeiro | C37: 4215.44 | D37: 0.00262 | F37: AIRELA | G37: 305166.81 | H37: 190948.18 | I37: =IFERROR(Tabela517[[#This Row],[25. Fat.]]/Tabela517[[#This Row],[24. Fat]],"") -> 1.5981656 | L37: NEO QUIMICA | M37: =SUMIFS(Tabela113[Valor],Tabela113[Empresa],Tabela618[[#This Row],[Empresa]],Tabela113[Mês],$M$20) -> 26524.6 | N37: =SUMIFS(Tabela18[Valor],Tabela18[Empresa],Tabela618[[#This Row],[Empresa]],Tabela18[Mês],'25. BANCO DE DADOS'!$M$20) -> 13213.33 | O37: =IFERROR(Tabela618[[#This Row],[25. Fat.]]/Tabela618[[#This Row],[24. Fat]],"") -> 2.0074122
A38: ROSA SELVAGEM | B38: Janeiro | C38: 3845.04 | D38: 0.002389 | F38: BELLIZ | G38: 304795.14 | H38: 163739.17 | I38: =IFERROR(Tabela517[[#This Row],[25. Fat.]]/Tabela517[[#This Row],[24. Fat]],"") -> 1.8614675 | L38: GLOBO | M38: =SUMIFS(Tabela113[Valor],Tabela113[Empresa],Tabela618[[#This Row],[Empresa]],Tabela113[Mês],$M$20) -> 26378.97 | N38: =SUMIFS(Tabela18[Valor],Tabela18[Empresa],Tabela618[[#This Row],[Empresa]],Tabela18[Mês],'25. BANCO DE DADOS'!$M$20) -> 8099 | O38: =IFERROR(Tabela618[[#This Row],[25. Fat.]]/Tabela618[[#This Row],[24. Fat]],"") -> 3.2570651
A39: NATIVITA | B39: Janeiro | C39: 3232.97 | D39: 0.002009 | F39: BRASTERAPICA | G39: 295326.36 | H39: 97668.37 | I39: =IFERROR(Tabela517[[#This Row],[25. Fat.]]/Tabela517[[#This Row],[24. Fat]],"") -> 3.0237667 | L39: ELOFAR | M39: =SUMIFS(Tabela113[Valor],Tabela113[Empresa],Tabela618[[#This Row],[Empresa]],Tabela113[Mês],$M$20) -> 25824.04 | N39: =SUMIFS(Tabela18[Valor],Tabela18[Empresa],Tabela618[[#This Row],[Empresa]],Tabela18[Mês],'25. BANCO DE DADOS'!$M$20) -> 44556.61 | O39: =IFERROR(Tabela618[[#This Row],[25. Fat.]]/Tabela618[[#This Row],[24. Fat]],"") -> 0.5795782
A40: UNIPHAR | B40: Janeiro | C40: 2993.08 | D40: 0.00186 | F40: ELOFAR | G40: 213676.22 | H40: 92178.42 | I40: =IFERROR(Tabela517[[#This Row],[25. Fat.]]/Tabela517[[#This Row],[24. Fat]],"") -> 2.3180721 | L40: LEGRAND | M40: =SUMIFS(Tabela113[Valor],Tabela113[Empresa],Tabela618[[#This Row],[Empresa]],Tabela113[Mês],$M$20) -> 25359.28 | N40: =SUMIFS(Tabela18[Valor],Tabela18[Empresa],Tabela618[[#This Row],[Empresa]],Tabela18[Mês],'25. BANCO DE DADOS'!$M$20) -> 5949.22 | O40: =IFERROR(Tabela618[[#This Row],[25. Fat.]]/Tabela618[[#This Row],[24. Fat]],"") -> 4.2626227
...

Sheet MÊS ATUAL vs MÊS ANTERIOR
A1: Ranking Mensal
A3: Pesquisa Mês:
A4: Laboratótios | B4: MAIO | C4: Laboratótios 2 | D4: ABRIL
A5: BIOSINTETICA (ACHE) | B5: 232744.75 | C5: BIOSINTETICA (ACHE) | D5: 221129.68
A6: GEOLAB | B6: 220603.49 | C6: TEUTO | D6: 211834.38
A7: TEUTO | B7: 209831.35 | C7: EMS MARCAS | D7: 157013.47
A8: EMS MARCAS | B8: 184682.27 | C8: GEOLAB | D8: 153197.1
A9: PRUDENCE | B9: 178689.55 | C9: FORTLIFE | D9: 118446.92
A10: GLOBO | B10: 124362.27 | C10: HIDROLIGHT | D10: 96389.2
A11: FORTLIFE | B11: 119077.16 | C11: NATULAB | D11: 72694.87
A12: HIDROLIGHT | B12: 86358.43 | C12: PRUDENCE | D12: 58579.4
A13: NEO QUIMICA | B13: 74945.05 | C13: BRASTERAPICA | D13: 56829.31
A14: MAXINUTRI | B14: 55813.3 | C14: MAXINUTRI | D14: 49734.37
A15: NATULAB | B15: 52743.23 | C15: NUK | D15: 44156.62
A16: MY HEALTH | B16: 45041.21 | C16: NEO QUIMICA | D16: 43178.79
... A94: BD PLASTIPAK | B94: 6.4 | C94: CALYPSO | D94: 8.88
C95: MILI S/A | D95: 4.38
C96: BD PLASTIPAK | D96: 3.36
